Workbook
Name Interval: #REF!
Name ScheduleStart: #REF!

Sheet 5 YEARS_Annual Profit and Loss
B1: 5 Years Income Projection/Analysis
B2: John's Bakery | F2: Income Statement | K2: *Please enter values in white cells only. Cells in gray will be automatically populated based on data input.
B3: 1234 Anytown | F3: DATE PREPARED | H3: 47119 | K3: *User, please enter all values as positive, except as indicated.
B4: NY, NY 45871 | G4: START YEAR | H4: 2024
B5: Phone: (XXX) XXX-XXXX | G5: END YEAR | H5: =H4+4 -> 2028 | K5: Attention users: Please be aware that the summary table is currently linked to row 34 for interest expense in order to calculate EBIT. If you need to modify the descriptions of operating expenses, please ensure that you update the formula in the summary table accordingly. This will ensure accurate calculation of EBIT.
D7: For the Years Ended
B9: REVENUE | C9: TREND | D9: =H4 -> 2024 | E9: =D9+1 -> 2025 | F9: =D9+2 -> 2026 | G9: =D9+3 -> 2027 | H9: =D9+4 -> 2028
B10: Gross Sales | D10: 87000 | E10: 65000 | F10: 45000 | G10: 150000 | H10: 205000
B11: Less Sales Discounts (enter as negative) | D11: -5000 | E11: -5500 | F11: -1000 | G11: -6500 | H11: -7000
B12: Less Sales Returns (enter as negative) | D12: -1000 | E12: -50 | F12: -600 | G12: -700 | H12: -800
B13: NET SALES | D13: =SUM(D10:D12) -> 81000 | E13: =SUM(E10:E12) -> 59450 | F13: =SUM(F10:F12) -> 43400 | G13: =SUM(G10:G12) -> 142800 | H13: =SUM(H10:H12) -> 197200
B15: COST OF SALES | D15: =D9 -> 2024 | E15: =E9 -> 2025 | F15: =F9 -> 2026 | G15: =G9 -> 2027 | H15: =H9 -> 2028
B16: Cost of Goods Sold | D16: 6700 | E16: 5000 | F16: 20000 | G16: 25000 | H16: 30000
B17: TOTAL COST OF GOODS SOLD (COGS) | D17: =D16 -> 6700 | E17: =E16 -> 5000 | F17: =F16 -> 20000 | G17: =G16 -> 25000 | H17: =H16 -> 30000
B19: GROSS PROFIT (LOSS) | D19: =D13-D17 -> 74300 | E19: =E13-E17 -> 54450 | F19: =F13-F17 -> 23400 | G19: =G13-G17 -> 117800 | H19: =H13-H17 -> 167200
B21: OPERATING EXPENSES | D21: =D9 -> 2024 | E21: =E9 -> 2025 | F21: =F9 -> 2026 | G21: =G9 -> 2027 | H21: =H9 -> 2028
B22: Marketing & Advertising | D22: 500 | E22: 600 | F22: 100 | G22: 800 | H22: 900
B23: Salaries & Wages | D23: 1500 | E23: 500 | F23: 3500 | G23: 4500 | H23: 5500
B24: Payroll Benefits & Taxes | D24: 100 | E24: 600 | F24: 300 | G24: 200 | H24: 1000
B25: Travel & Entertainment | D25: 100 | E25: 360 | F25: 300 | G25: 400 | H25: 500
B26: Web Hosting and maintenance | D26: 250 | E26: 100 | F26: 450 | G26: 100 | H26: 650
B27: Stationary | D27: 50 | E27: 55 | F27: 60 | G27: 65 | H27: 75
B28: Rent | D28: 1500 | E28: 1150 | F28: 1600 | G28: 1800 | H28: 2000
B29: Utilities | D29: 1500 | E29: 1000 | F29: 1500 | G29: 250 | H29: 3500
B30: Office Supplies | D30: 250 | E30: 110 | F30: 75 | G30: 85 | H30: 50
B31: Professional Fees | D31: 1000 | E31: 100 | F31: 250 | G31: 75 | H31: 1000
B32: Insurance | D32: 150 | E32: 55 | F32: 75 | G32: 800 | H32: 150
B33: Depreciation | D33: 1000 | E33: 1100 | F33: 1210 | G33: 1331 | H33: 1464.1
... B39: Other Operating Expenses5 | D39: 550 | E39: 450 | F39: 150 | G39: 250 | H39: 110
B40: TOTAL OPERATING EXPENSES | D40: =SUM(D22:D39) -> 12150 | E40: =SUM(E22:E39) -> 10195 | F40: =SUM(F22:F39) -> 12290.5 | G40: =SUM(G22:G39) -> 13268.55 | H40: =SUM(H22:H39) -> 19696.42
B43: NET INCOME BEFORE TAXES | D43: =D19-D40 -> 62150 | E43: =E19-E40 -> 44255 | F43: =F19-F40 -> 11109.5 | G43: =G19-G40 -> 104531.45 | H43: =H19-H40 -> 147503.58
B44: Income Tax | D44: 1215 | E44: 1019.5 | F44: 1229.05 | G44: 1326.86 | H44: 1969.64
B45: NET INCOME AFTER TAXES | D45: =D43-D44 -> 60935 | E45: =E43-E44 -> 43235.5 | F45: =F43-F44 -> 9880.45 | G45: =G43-G44 -> 103204.59 | H45: =H43-H44 -> 145533.94
B48: SUMMARY ANALYSIS
B50: Revenue | D50: =D9 -> 2024 | E50: =E9 -> 2025 | F50: =F9 -> 2026 | G50: =G9 -> 2027 | H50: =H9 -> 2028
B51: Net Sales | D51: =D13 -> 81000 | E51: =E13 -> 59450 | F51: =F13 -> 43400 | G51: =G13 -> 142800 | H51: =H13 -> 197200
B52: Direct Cost | D52: =D17 -> 6700 | E52: =E17 -> 5000 | F52: =F17 -> 20000 | G52: =G17 -> 25000 | H52: =H17 -> 30000
B53: Gross Margin (Profit) | D53: =D51-D52 -> 74300 | E53: =E51-E52 -> 54450 | F53: =F51-F52 -> 23400 | G53: =G51-G52 -> 117800 | H53: =H51-H52 -> 167200
B54: Gross Margin% | D54: =IFERROR(D53/D51,"-") -> 0.91728395 | E54: =IFERROR(E53/E51,"-") -> 0.91589571 | F54: =IFERROR(F53/F51,"-") -> 0.53917051 | G54: =IFERROR(G53/G51,"-") -> 0.82492997 | H54: =IFERROR(H53/H51,"-") -> 0.84787018
B56: Expenses | D56: =D50 -> 2024 | E56: =E50 -> 2025 | F56: =F50 -> 2026 | G56: =G50 -> 2027 | H56: =H50 -> 2028
...

Sheet BackEnd_DoNOT DELETE
B5: =-'5 YEARS_Annual Profit and Loss'!D11 -> 5000 | C5: =-'5 YEARS_Annual Profit and Loss'!E11 -> 5500 | D5: =-'5 YEARS_Annual Profit and Loss'!F11 -> 1000 | E5: =-'5 YEARS_Annual Profit and Loss'!G11 -> 6500
B6: =-'5 YEARS_Annual Profit and Loss'!D12 -> 1000 | C6: =-'5 YEARS_Annual Profit and Loss'!E12 -> 50 | D6: =-'5 YEARS_Annual Profit and Loss'!F12 -> 600 | E6: =-'5 YEARS_Annual Profit and Loss'!G12 -> 700
